<?xml version="1.0" encoding="utf-8"?>
<!-- =================================================================================== -->
<!-- |    This document was autogenerated by xacro from src/suturo_resources/suturo_resources/urdf/suturo_rooms.urdf.xacro | -->
<!-- |    EDITING THIS FILE BY HAND IS NOT RECOMMENDED                                 | -->
<!-- =================================================================================== -->
<robot name="suturo_rooms">
  <!--<xacro:property name="data"
    value="${load_yaml('$(arg yaml_file)')}" />-->
  <material name="wall_red">
    <color rgba="0.75 0.22 0.17 1"/>
  </material>
  <material name="door_green">
    <color rgba="0 0.31 0.22 1"/>
  </material>
  <material name="hinge_red">
    <color rgba="0.74 0.25 0.25 1"/>
  </material>
  <material name="handle_blue">
    <color rgba="0.3 0.5 0.78 1"/>
  </material>
  <joint name="wall_0_center_joint" type="fixed">
    <origin xyz="-4.5 0.5 0.3"/>
    <parent link="urdf_offset"/>
    <child link="wall_0_link"/>
  </joint>
  <link name="wall_0_link">
    <visual>
      <material name="wall_red"/>
      <origin rpy="0 0 1.57079632679" xyz="0 0 0"/>
      <geometry>
        <box size="9.0 0.02 0.6"/>
      </geometry>
    </visual>
    <collision>
      <origin rpy="0 0 1.57079632679" xyz="0 0 0"/>
      <geometry>
        <box size="9.0 0.02 0.6"/>
      </geometry>
    </collision>
  </link>
  <joint name="wall_1_center_joint" type="fixed">
    <origin xyz="-3.0 0.75 0.3"/>
    <parent link="urdf_offset"/>
    <child link="wall_1_link"/>
  </joint>
  <link name="wall_1_link">
    <visual>
      <material name="wall_red"/>
      <origin rpy="0 0 1.57079632679" xyz="0 0 0"/>
      <geometry>
        <box size="4.5 0.02 0.6"/>
      </geometry>
    </visual>
    <collision>
      <origin rpy="0 0 1.57079632679" xyz="0 0 0"/>
      <geometry>
        <box size="4.5 0.02 0.6"/>
      </geometry>
    </collision>
  </link>
  <joint name="wall_2_center_joint" type="fixed">
    <origin xyz="-3.0 -0.25 0.3"/>
    <parent link="urdf_offset"/>
    <child link="wall_2_link"/>
  </joint>
  <link name="wall_2_link">
    <visual>
      <material name="wall_red"/>
      <origin rpy="0 0 1.57079632679" xyz="0 0 0"/>
      <geometry>
        <box size="2.5 0.02 0.6"/>
      </geometry>
    </visual>
    <collision>
      <origin rpy="0 0 1.57079632679" xyz="0 0 0"/>
      <geometry>
        <box size="2.5 0.02 0.6"/>
      </geometry>
    </collision>
  </link>
  <joint name="wall_3_center_joint" type="fixed">
    <origin xyz="-3.0 -3.25 0.3"/>
    <parent link="urdf_offset"/>
    <child link="wall_3_link"/>
  </joint>
  <link name="wall_3_link">
    <visual>
      <material name="wall_red"/>
      <origin rpy="0 0 1.57079632679" xyz="0 0 0"/>
      <geometry>
        <box size="1.5 0.02 0.6"/>
      </geometry>
    </visual>
    <collision>
      <origin rpy="0 0 1.57079632679" xyz="0 0 0"/>
      <geometry>
        <box size="1.5 0.02 0.6"/>
      </geometry>
    </collision>
  </link>
  <joint name="wall_4_center_joint" type="fixed">
    <origin xyz="-2.0 4.75 0.3"/>
    <parent link="urdf_offset"/>
    <child link="wall_4_link"/>
  </joint>
  <link name="wall_4_link">
    <visual>
      <material name="wall_red"/>
      <origin rpy="0 0 1.57079632679" xyz="0 0 0"/>
      <geometry>
        <box size="0.5 0.02 0.6"/>
      </geometry>
    </visual>
    <collision>
      <origin rpy="0 0 1.57079632679" xyz="0 0 0"/>
      <geometry>
        <box size="0.5 0.02 0.6"/>
      </geometry>
    </collision>
  </link>
  <joint name="wall_5_center_joint" type="fixed">
    <origin xyz="-2.0 3.25 0.3"/>
    <parent link="urdf_offset"/>
    <child link="wall_5_link"/>
  </joint>
  <link name="wall_5_link">
    <visual>
      <material name="wall_red"/>
      <origin rpy="0 0 1.57079632679" xyz="0 0 0"/>
      <geometry>
        <box size="0.5 0.02 0.6"/>
      </geometry>
    </visual>
    <collision>
      <origin rpy="0 0 1.57079632679" xyz="0 0 0"/>
      <geometry>
        <box size="0.5 0.02 0.6"/>
      </geometry>
    </collision>
  </link>
  <joint name="wall_6_center_joint" type="fixed">
    <origin xyz="0.0 -3.25 0.3"/>
    <parent link="urdf_offset"/>
    <child link="wall_6_link"/>
  </joint>
  <link name="wall_6_link">
    <visual>
      <material name="wall_red"/>
      <origin rpy="0 0 1.57079632679" xyz="0 0 0"/>
      <geometry>
        <box size="1.5 0.02 0.6"/>
      </geometry>
    </visual>
    <collision>
      <origin rpy="0 0 1.57079632679" xyz="0 0 0"/>
      <geometry>
        <box size="1.5 0.02 0.6"/>
      </geometry>
    </collision>
  </link>
  <joint name="wall_7_center_joint" type="fixed">
    <origin xyz="0.0 0.75 0.3"/>
    <parent link="urdf_offset"/>
    <child link="wall_7_link"/>
  </joint>
  <link name="wall_7_link">
    <visual>
      <material name="wall_red"/>
      <origin rpy="0 0 1.57079632679" xyz="0 0 0"/>
      <geometry>
        <box size="4.5 0.02 0.6"/>
      </geometry>
    </visual>
    <collision>
      <origin rpy="0 0 1.57079632679" xyz="0 0 0"/>
      <geometry>
        <box size="4.5 0.02 0.6"/>
      </geometry>
    </collision>
  </link>
  <joint name="wall_8_center_joint" type="fixed">
    <origin xyz="3.0 1.0 0.3"/>
    <parent link="urdf_offset"/>
    <child link="wall_8_link"/>
  </joint>
  <link name="wall_8_link">
    <visual>
      <material name="wall_red"/>
      <origin rpy="0 0 1.57079632679" xyz="0 0 0"/>
      <geometry>
        <box size="8.0 0.02 0.6"/>
      </geometry>
    </visual>
    <collision>
      <origin rpy="0 0 1.57079632679" xyz="0 0 0"/>
      <geometry>
        <box size="8.0 0.02 0.6"/>
      </geometry>
    </collision>
  </link>
  <joint name="wall_9_center_joint" type="fixed">
    <origin xyz="-0.75 5.0 0.3"/>
    <parent link="urdf_offset"/>
    <child link="wall_9_link"/>
  </joint>
  <link name="wall_9_link">
    <visual>
      <material name="wall_red"/>
      <origin rpy="0 0 0.0" xyz="0 0 0"/>
      <geometry>
        <box size="7.5 0.02 0.6"/>
      </geometry>
    </visual>
    <collision>
      <origin rpy="0 0 0.0" xyz="0 0 0"/>
      <geometry>
        <box size="7.5 0.02 0.6"/>
      </geometry>
    </collision>
  </link>
  <joint name="wall_10_center_joint" type="fixed">
    <origin xyz="-2.25 3.0 0.3"/>
    <parent link="urdf_offset"/>
    <child link="wall_10_link"/>
  </joint>
  <link name="wall_10_link">
    <visual>
      <material name="wall_red"/>
      <origin rpy="0 0 0.0" xyz="0 0 0"/>
      <geometry>
        <box size="1.5 0.02 0.6"/>
      </geometry>
    </visual>
    <collision>
      <origin rpy="0 0 0.0" xyz="0 0 0"/>
      <geometry>
        <box size="1.5 0.02 0.6"/>
      </geometry>
    </collision>
  </link>
  <joint name="wall_11_center_joint" type="fixed">
    <origin xyz="-0.25 3.0 0.3"/>
    <parent link="urdf_offset"/>
    <child link="wall_11_link"/>
  </joint>
  <link name="wall_11_link">
    <visual>
      <material name="wall_red"/>
      <origin rpy="0 0 0.0" xyz="0 0 0"/>
      <geometry>
        <box size="0.5 0.02 0.6"/>
      </geometry>
    </visual>
    <collision>
      <origin rpy="0 0 0.0" xyz="0 0 0"/>
      <geometry>
        <box size="0.5 0.02 0.6"/>
      </geometry>
    </collision>
  </link>
  <joint name="wall_12_center_joint" type="fixed">
    <origin xyz="-1.5 0.0 0.3"/>
    <parent link="urdf_offset"/>
    <child link="wall_12_link"/>
  </joint>
  <link name="wall_12_link">
    <visual>
      <material name="wall_red"/>
      <origin rpy="0 0 0.0" xyz="0 0 0"/>
      <geometry>
        <box size="3.0 0.02 0.6"/>
      </geometry>
    </visual>
    <collision>
      <origin rpy="0 0 0.0" xyz="0 0 0"/>
      <geometry>
        <box size="3.0 0.02 0.6"/>
      </geometry>
    </collision>
  </link>
  <joint name="wall_13_center_joint" type="fixed">
    <origin xyz="-2.25 -4.0 0.3"/>
    <parent link="urdf_offset"/>
    <child link="wall_13_link"/>
  </joint>
  <link name="wall_13_link">
    <visual>
      <material name="wall_red"/>
      <origin rpy="0 0 0.0" xyz="0 0 0"/>
      <geometry>
        <box size="4.5 0.02 0.6"/>
      </geometry>
    </visual>
    <collision>
      <origin rpy="0 0 0.0" xyz="0 0 0"/>
      <geometry>
        <box size="4.5 0.02 0.6"/>
      </geometry>
    </collision>
  </link>
  <joint name="wall_14_center_joint" type="fixed">
    <origin xyz="1.5 -3.5 0.3"/>
    <parent link="urdf_offset"/>
    <child link="wall_14_link"/>
  </joint>
  <link name="wall_14_link">
    <visual>
      <material name="wall_red"/>
      <origin rpy="0 0 0.321750554397" xyz="0 0 0"/>
      <geometry>
        <box size="3.16227766017 0.02 0.6"/>
      </geometry>
    </visual>
    <collision>
      <origin rpy="0 0 0.321750554397" xyz="0 0 0"/>
      <geometry>
        <box size="3.16227766017 0.02 0.6"/>
      </geometry>
    </collision>
  </link>
  <!-- define a central joint to wich every corner is connected -->
  <joint name="world_kitchen_room_joint" type="fixed">
    <origin rpy="0 0 0" xyz="-1.5 -2 0 "/>
    <parent link="urdf_offset"/>
    <child link="kitchen_room_center_link"/>
  </joint>
  <link name="kitchen_room_center_link">
    <visual>
      <geometry>
        <cylinder length="0" radius="0"/>
      </geometry>
      <material name="color">
        <color rgba="1 0.51 0.66 0.5"/>
      </material>
    </visual>
  </link>
  <joint name="kitchen_room_joint_0" type="fixed">
    <origin rpy="0 0 0" xyz="-1.5 -2 0 "/>
    <parent link="kitchen_room_center_link"/>
    <child link="kitchen_room_corner_0_link"/>
  </joint>
  <link name="kitchen_room_corner_0_link"/>
  <joint name="kitchen_room_joint_1" type="fixed">
    <origin rpy="0 0 0" xyz="1.5 -2 0 "/>
    <parent link="kitchen_room_center_link"/>
    <child link="kitchen_room_corner_1_link"/>
  </joint>
  <link name="kitchen_room_corner_1_link"/>
  <joint name="kitchen_room_joint_2" type="fixed">
    <origin rpy="0 0 0" xyz="1.5 2 0 "/>
    <parent link="kitchen_room_center_link"/>
    <child link="kitchen_room_corner_2_link"/>
  </joint>
  <link name="kitchen_room_corner_2_link"/>
  <joint name="kitchen_room_joint_3" type="fixed">
    <origin rpy="0 0 0" xyz="-1.5 2 0 "/>
    <parent link="kitchen_room_center_link"/>
    <child link="kitchen_room_corner_3_link"/>
  </joint>
  <link name="kitchen_room_corner_3_link"/>
  <!-- define a central joint to wich every corner is connected -->
  <joint name="world_living-room_room_joint" type="fixed">
    <origin rpy="0 0 0" xyz="1.5 3 0 "/>
    <parent link="urdf_offset"/>
    <child link="living-room_room_center_link"/>
  </joint>
  <link name="living-room_room_center_link">
    <visual>
      <geometry>
        <cylinder length="0" radius="0"/>
      </geometry>
      <material name="color">
        <color rgba="0.57 1 0.1 0.5"/>
      </material>
    </visual>
  </link>
  <joint name="living-room_room_joint_0" type="fixed">
    <origin rpy="0 0 0" xyz="-1.5 -3 0 "/>
    <parent link="living-room_room_center_link"/>
    <child link="living-room_room_corner_0_link"/>
  </joint>
  <link name="living-room_room_corner_0_link"/>
  <joint name="living-room_room_joint_1" type="fixed">
    <origin rpy="0 0 0" xyz="1.5 -3 0 "/>
    <parent link="living-room_room_center_link"/>
    <child link="living-room_room_corner_1_link"/>
  </joint>
  <link name="living-room_room_corner_1_link"/>
  <joint name="living-room_room_joint_2" type="fixed">
    <origin rpy="0 0 0" xyz="1.5 2 0 "/>
    <parent link="living-room_room_center_link"/>
    <child link="living-room_room_corner_2_link"/>
  </joint>
  <link name="living-room_room_corner_2_link"/>
  <joint name="living-room_room_joint_3" type="fixed">
    <origin rpy="0 0 0" xyz="-3.5 2 0 "/>
    <parent link="living-room_room_center_link"/>
    <child link="living-room_room_corner_3_link"/>
  </joint>
  <link name="living-room_room_corner_3_link"/>
  <joint name="living-room_room_joint_4" type="fixed">
    <origin rpy="0 0 0" xyz="-3.5 0 0 "/>
    <parent link="living-room_room_center_link"/>
    <child link="living-room_room_corner_4_link"/>
  </joint>
  <link name="living-room_room_corner_4_link"/>
  <joint name="living-room_room_joint_5" type="fixed">
    <origin rpy="0 0 0" xyz="-1.5 0 0 "/>
    <parent link="living-room_room_center_link"/>
    <child link="living-room_room_corner_5_link"/>
  </joint>
  <link name="living-room_room_corner_5_link"/>
  <!-- define a central joint to wich every corner is connected -->
  <joint name="world_sleeping-room_room_joint" type="fixed">
    <origin rpy="0 0 0" xyz="-1.5 1.5 0 "/>
    <parent link="urdf_offset"/>
    <child link="sleeping-room_room_center_link"/>
  </joint>
  <link name="sleeping-room_room_center_link">
    <visual>
      <geometry>
        <cylinder length="0" radius="0"/>
      </geometry>
      <material name="color">
        <color rgba="0.57 1 0.1 0.5"/>
      </material>
    </visual>
  </link>
  <joint name="sleeping-room_room_joint_0" type="fixed">
    <origin rpy="0 0 0" xyz="-1.5 -1.5 0 "/>
    <parent link="sleeping-room_room_center_link"/>
    <child link="sleeping-room_room_corner_0_link"/>
  </joint>
  <link name="sleeping-room_room_corner_0_link"/>
  <joint name="sleeping-room_room_joint_1" type="fixed">
    <origin rpy="0 0 0" xyz="1.5 -1.5 0 "/>
    <parent link="sleeping-room_room_center_link"/>
    <child link="sleeping-room_room_corner_1_link"/>
  </joint>
  <link name="sleeping-room_room_corner_1_link"/>
  <joint name="sleeping-room_room_joint_2" type="fixed">
    <origin rpy="0 0 0" xyz="1.5 1.5 0 "/>
    <parent link="sleeping-room_room_center_link"/>
    <child link="sleeping-room_room_corner_2_link"/>
  </joint>
  <link name="sleeping-room_room_corner_2_link"/>
  <joint name="sleeping-room_room_joint_3" type="fixed">
    <origin rpy="0 0 0" xyz="-1.5 1.5 0 "/>
    <parent link="sleeping-room_room_center_link"/>
    <child link="sleeping-room_room_corner_3_link"/>
  </joint>
  <link name="sleeping-room_room_corner_3_link"/>
  <!-- define a central joint to wich every corner is connected -->
  <joint name="world_office_room_joint" type="fixed">
    <origin rpy="0 0 0" xyz="1.5 -1.5 0 "/>
    <parent link="urdf_offset"/>
    <child link="office_room_center_link"/>
  </joint>
  <link name="office_room_center_link">
    <visual>
      <geometry>
        <cylinder length="0" radius="0"/>
      </geometry>
      <material name="color">
        <color rgba="0.57 1 0.1 0.5"/>
      </material>
    </visual>
  </link>
  <joint name="office_room_joint_0" type="fixed">
    <origin rpy="0 0 0" xyz="-1.5 -2.5 0 "/>
    <parent link="office_room_center_link"/>
    <child link="office_room_corner_0_link"/>
  </joint>
  <link name="office_room_corner_0_link"/>
  <joint name="office_room_joint_1" type="fixed">
    <origin rpy="0 0 0" xyz="1.5 -1.5 0 "/>
    <parent link="office_room_center_link"/>
    <child link="office_room_corner_1_link"/>
  </joint>
  <link name="office_room_corner_1_link"/>
  <joint name="office_room_joint_2" type="fixed">
    <origin rpy="0 0 0" xyz="1.5 1.5 0 "/>
    <parent link="office_room_center_link"/>
    <child link="office_room_corner_2_link"/>
  </joint>
  <link name="office_room_corner_2_link"/>
  <joint name="office_room_joint_3" type="fixed">
    <origin rpy="0 0 0" xyz="-1.5 1.5 0 "/>
    <parent link="office_room_center_link"/>
    <child link="office_room_corner_3_link"/>
  </joint>
  <link name="office_room_corner_3_link"/>
  <!-- define a central joint to wich every corner is connected -->
  <joint name="world_hall_room_joint" type="fixed">
    <origin rpy="0 0 0" xyz="-3.75 1 0 "/>
    <parent link="urdf_offset"/>
    <child link="hall_room_center_link"/>
  </joint>
  <link name="hall_room_center_link">
    <visual>
      <geometry>
        <cylinder length="0" radius="0"/>
      </geometry>
      <material name="color">
        <color rgba="0.57 1 0.1 0.5"/>
      </material>
    </visual>
  </link>
  <joint name="hall_room_joint_0" type="fixed">
    <origin rpy="0 0 0" xyz="-0.75 -5 0 "/>
    <parent link="hall_room_center_link"/>
    <child link="hall_room_corner_0_link"/>
  </joint>
  <link name="hall_room_corner_0_link"/>
  <joint name="hall_room_joint_1" type="fixed">
    <origin rpy="0 0 0" xyz="0.75 -5 0 "/>
    <parent link="hall_room_center_link"/>
    <child link="hall_room_corner_1_link"/>
  </joint>
  <link name="hall_room_corner_1_link"/>
  <joint name="hall_room_joint_2" type="fixed">
    <origin rpy="0 0 0" xyz="0.75 2 0 "/>
    <parent link="hall_room_center_link"/>
    <child link="hall_room_corner_2_link"/>
  </joint>
  <link name="hall_room_corner_2_link"/>
  <joint name="hall_room_joint_3" type="fixed">
    <origin rpy="0 0 0" xyz="1.75 2 0 "/>
    <parent link="hall_room_center_link"/>
    <child link="hall_room_corner_3_link"/>
  </joint>
  <link name="hall_room_corner_3_link"/>
  <joint name="hall_room_joint_4" type="fixed">
    <origin rpy="0 0 0" xyz="1.75 4 0 "/>
    <parent link="hall_room_center_link"/>
    <child link="hall_room_corner_4_link"/>
  </joint>
  <link name="hall_room_corner_4_link"/>
  <joint name="hall_room_joint_5" type="fixed">
    <origin rpy="0 0 0" xyz="-0.75 4 0 "/>
    <parent link="hall_room_center_link"/>
    <child link="hall_room_corner_5_link"/>
  </joint>
  <link name="hall_room_corner_5_link"/>
  <!-- LINKS -->
  <link name="door_hall_living-room_1_door_center">
    <visual>
      <material name="door_green"/>
      <origin rpy="0 0 0" xyz="0.5 0 0"/>
      <geometry>
        <box size="1.0 0.055 2"/>
      </geometry>
    </visual>
    <collision>
      <origin rpy="0 0 0" xyz="0.5 0 0"/>
      <geometry>
        <box size="1.0 0.055 2"/>
      </geometry>
    </collision>
  </link>
  <link name="door_hall_living-room_1_door_hinge">
    <visual>
      <material name="hinge_red"/>
      <origin rpy="0 0 0" xyz="0 0 0"/>
      <geometry>
        <box size="0.05 0.05 2"/>
      </geometry>
    </visual>
    <collision>
      <origin rpy="0 0 0" xyz="0 0 0"/>
      <geometry>
        <box size="0.05 0.05 2"/>
      </geometry>
    </collision>
  </link>
  <link name="door_hall_living-room_1_door_handle_outside">
    <sphere_inertia mass="0" radius="0"/>
    <visual>
      <material name="handle_blue"/>
      <origin rpy="1.570796327 0 3.14159265359" xyz="0 0 0"/>
      <geometry>
        <box size="0.15 0.025 0.015"/>
      </geometry>
    </visual>
    <collision>
      <origin rpy="1.570796327 0 3.14159265359" xyz="0 0 0"/>
      <geometry>
        <box size="0.15 0.025 0.015"/>
      </geometry>
    </collision>
  </link>
  <link name="door_hall_living-room_1_door_handle_inside">
    <sphere_inertia mass="0" radius="0"/>
    <visual>
      <material name="handle_blue"/>
      <origin rpy="1.570796327 0 3.14159265359" xyz="0 0 0"/>
      <geometry>
        <box size="0.15 0.025 0.015"/>
      </geometry>
    </visual>
    <collision>
      <origin rpy="1.570796327 0 3.14159265359" xyz="0 0 0"/>
      <geometry>
        <box size="0.15 0.025 0.015"/>
      </geometry>
    </collision>
  </link>
  <!-- JOINTS -->
  <joint name="door_hall_living-room_1_door_origin_revolute_joint" type="revolute">
    <axis xyz="0 0 1"/>
    <limit effort="100" lower="0" upper="1.5708" velocity="10"/>
    <origin rpy="0 0 1.57079632679" xyz="0 0 0"/>
    <parent link="door_hall_living-room_1_door_hinge"/>
    <child link="door_hall_living-room_1_door_center"/>
  </joint>
  <joint name="door_hall_living-room_1_door_hinge_joint" type="fixed">
    <axis xyz="0 0 0"/>
    <limit effort="1" lower="0" upper="1.5708" velocity="1"/>
    <origin rpy="0 0 0" xyz="-2 3.5 1.045"/>
    <parent link="urdf_offset"/>
    <child link="door_hall_living-room_1_door_hinge"/>
  </joint>
  <joint name="door_hall_living-room_1_door_handle_inside_joint" type="fixed">
    <axis xyz="0 0 0"/>
    <limit effort="1" lower="0" upper="1.5708" velocity="1"/>
    <origin rpy="0 0 0" xyz="0.9 -0.06875 -0.13"/>
    <parent link="door_hall_living-room_1_door_center"/>
    <child link="door_hall_living-room_1_door_handle_inside"/>
  </joint>
  <joint name="door_hall_living-room_1_door_handle_outside_joint" type="fixed">
    <axis xyz="0 0 0"/>
    <limit effort="1" lower="0" upper="1.5708" velocity="1"/>
    <origin rpy="0 0 0" xyz="0.9 0.055 -0.13"/>
    <parent link="door_hall_living-room_1_door_center"/>
    <child link="door_hall_living-room_1_door_handle_outside"/>
  </joint>
  <!-- LINKS -->
  <link name="door_hall_sleeping-room_1_door_center">
    <visual>
      <material name="door_green"/>
      <origin rpy="0 0 0" xyz="0.5 0 0"/>
      <geometry>
        <box size="1.0 0.055 2"/>
      </geometry>
    </visual>
    <collision>
      <origin rpy="0 0 0" xyz="0.5 0 0"/>
      <geometry>
        <box size="1.0 0.055 2"/>
      </geometry>
    </collision>
  </link>
  <link name="door_hall_sleeping-room_1_door_hinge">
    <visual>
      <material name="hinge_red"/>
      <origin rpy="0 0 0" xyz="0 0 0"/>
      <geometry>
        <box size="0.05 0.05 2"/>
      </geometry>
    </visual>
    <collision>
      <origin rpy="0 0 0" xyz="0 0 0"/>
      <geometry>
        <box size="0.05 0.05 2"/>
      </geometry>
    </collision>
  </link>
  <link name="door_hall_sleeping-room_1_door_handle_outside">
    <sphere_inertia mass="0" radius="0"/>
    <visual>
      <material name="handle_blue"/>
      <origin rpy="1.570796327 0 3.14159265359" xyz="0 0 0"/>
      <geometry>
        <box size="0.15 0.025 0.015"/>
      </geometry>
    </visual>
    <collision>
      <origin rpy="1.570796327 0 3.14159265359" xyz="0 0 0"/>
      <geometry>
        <box size="0.15 0.025 0.015"/>
      </geometry>
    </collision>
  </link>
  <link name="door_hall_sleeping-room_1_door_handle_inside">
    <sphere_inertia mass="0" radius="0"/>
    <visual>
      <material name="handle_blue"/>
      <origin rpy="1.570796327 0 3.14159265359" xyz="0 0 0"/>
      <geometry>
        <box size="0.15 0.025 0.015"/>
      </geometry>
    </visual>
    <collision>
      <origin rpy="1.570796327 0 3.14159265359" xyz="0 0 0"/>
      <geometry>
        <box size="0.15 0.025 0.015"/>
      </geometry>
    </collision>
  </link>
  <!-- JOINTS -->
  <joint name="door_hall_sleeping-room_1_door_origin_revolute_joint" type="revolute">
    <axis xyz="0 0 1"/>
    <limit effort="100" lower="0" upper="1.5708" velocity="10"/>
    <origin rpy="0 0 1.57079632679" xyz="0 0 0"/>
    <parent link="door_hall_sleeping-room_1_door_hinge"/>
    <child link="door_hall_sleeping-room_1_door_center"/>
  </joint>
  <joint name="door_hall_sleeping-room_1_door_hinge_joint" type="fixed">
    <axis xyz="0 0 0"/>
    <limit effort="1" lower="0" upper="1.5708" velocity="1"/>
    <origin rpy="0 0 0" xyz="-3 1.0 1.045"/>
    <parent link="urdf_offset"/>
    <child link="door_hall_sleeping-room_1_door_hinge"/>
  </joint>
  <joint name="door_hall_sleeping-room_1_door_handle_inside_joint" type="fixed">
    <axis xyz="0 0 0"/>
    <limit effort="1" lower="0" upper="1.5708" velocity="1"/>
    <origin rpy="0 0 0" xyz="0.9 -0.06875 -0.13"/>
    <parent link="door_hall_sleeping-room_1_door_center"/>
    <child link="door_hall_sleeping-room_1_door_handle_inside"/>
  </joint>
  <joint name="door_hall_sleeping-room_1_door_handle_outside_joint" type="fixed">
    <axis xyz="0 0 0"/>
    <limit effort="1" lower="0" upper="1.5708" velocity="1"/>
    <origin rpy="0 0 0" xyz="0.9 0.055 -0.13"/>
    <parent link="door_hall_sleeping-room_1_door_center"/>
    <child link="door_hall_sleeping-room_1_door_handle_outside"/>
  </joint>
  <!-- LINKS -->
  <link name="door_hall_kitchen_1_door_center">
    <visual>
      <material name="door_green"/>
      <origin rpy="0 0 0" xyz="0.5 0 0"/>
      <geometry>
        <box size="1.0 0.055 2"/>
      </geometry>
    </visual>
    <collision>
      <origin rpy="0 0 0" xyz="0.5 0 0"/>
      <geometry>
        <box size="1.0 0.055 2"/>
      </geometry>
    </collision>
  </link>
  <link name="door_hall_kitchen_1_door_hinge">
    <visual>
      <material name="hinge_red"/>
      <origin rpy="0 0 0" xyz="0 0 0"/>
      <geometry>
        <box size="0.05 0.05 2"/>
      </geometry>
    </visual>
    <collision>
      <origin rpy="0 0 0" xyz="0 0 0"/>
      <geometry>
        <box size="0.05 0.05 2"/>
      </geometry>
    </collision>
  </link>
  <link name="door_hall_kitchen_1_door_handle_outside">
    <sphere_inertia mass="0" radius="0"/>
    <visual>
      <material name="handle_blue"/>
      <origin rpy="1.570796327 0 3.14159265359" xyz="0 0 0"/>
      <geometry>
        <box size="0.15 0.025 0.015"/>
      </geometry>
    </visual>
    <collision>
      <origin rpy="1.570796327 0 3.14159265359" xyz="0 0 0"/>
      <geometry>
        <box size="0.15 0.025 0.015"/>
      </geometry>
    </collision>
  </link>
  <link name="door_hall_kitchen_1_door_handle_inside">
    <sphere_inertia mass="0" radius="0"/>
    <visual>
      <material name="handle_blue"/>
      <origin rpy="1.570796327 0 3.14159265359" xyz="0 0 0"/>
      <geometry>
        <box size="0.15 0.025 0.015"/>
      </geometry>
    </visual>
    <collision>
      <origin rpy="1.570796327 0 3.14159265359" xyz="0 0 0"/>
      <geometry>
        <box size="0.15 0.025 0.015"/>
      </geometry>
    </collision>
  </link>
  <!-- JOINTS -->
  <joint name="door_hall_kitchen_1_door_origin_revolute_joint" type="revolute">
    <axis xyz="0 0 1"/>
    <limit effort="100" lower="0" upper="1.5708" velocity="10"/>
    <origin rpy="0 0 1.57079632679" xyz="0 0 0"/>
    <parent link="door_hall_kitchen_1_door_hinge"/>
    <child link="door_hall_kitchen_1_door_center"/>
  </joint>
  <joint name="door_hall_kitchen_1_door_hinge_joint" type="fixed">
    <axis xyz="0 0 0"/>
    <limit effort="1" lower="0" upper="1.5708" velocity="1"/>
    <origin rpy="0 0 0" xyz="-3 -2.5 1.045"/>
    <parent link="urdf_offset"/>
    <child link="door_hall_kitchen_1_door_hinge"/>
  </joint>
  <joint name="door_hall_kitchen_1_door_handle_inside_joint" type="fixed">
    <axis xyz="0 0 0"/>
    <limit effort="1" lower="0" upper="1.5708" velocity="1"/>
    <origin rpy="0 0 0" xyz="0.9 -0.06875 -0.13"/>
    <parent link="door_hall_kitchen_1_door_center"/>
    <child link="door_hall_kitchen_1_door_handle_inside"/>
  </joint>
  <joint name="door_hall_kitchen_1_door_handle_outside_joint" type="fixed">
    <axis xyz="0 0 0"/>
    <limit effort="1" lower="0" upper="1.5708" velocity="1"/>
    <origin rpy="0 0 0" xyz="0.9 0.055 -0.13"/>
    <parent link="door_hall_kitchen_1_door_center"/>
    <child link="door_hall_kitchen_1_door_handle_outside"/>
  </joint>
  <!-- LINKS -->
  <link name="door_living-room_sleeping-room_1_door_center">
    <visual>
      <material name="door_green"/>
      <origin rpy="0 0 0" xyz="0.5 0 0"/>
      <geometry>
        <box size="1.0 0.055 2"/>
      </geometry>
    </visual>
    <collision>
      <origin rpy="0 0 0" xyz="0.5 0 0"/>
      <geometry>
        <box size="1.0 0.055 2"/>
      </geometry>
    </collision>
  </link>
  <link name="door_living-room_sleeping-room_1_door_hinge">
    <visual>
      <material name="hinge_red"/>
      <origin rpy="0 0 0" xyz="0 0 0"/>
      <geometry>
        <box size="0.05 0.05 2"/>
      </geometry>
    </visual>
    <collision>
      <origin rpy="0 0 0" xyz="0 0 0"/>
      <geometry>
        <box size="0.05 0.05 2"/>
      </geometry>
    </collision>
  </link>
  <link name="door_living-room_sleeping-room_1_door_handle_outside">
    <sphere_inertia mass="0" radius="0"/>
    <visual>
      <material name="handle_blue"/>
      <origin rpy="1.570796327 0 3.14159265359" xyz="0 0 0"/>
      <geometry>
        <box size="0.15 0.025 0.015"/>
      </geometry>
    </visual>
    <collision>
      <origin rpy="1.570796327 0 3.14159265359" xyz="0 0 0"/>
      <geometry>
        <box size="0.15 0.025 0.015"/>
      </geometry>
    </collision>
  </link>
  <link name="door_living-room_sleeping-room_1_door_handle_inside">
    <sphere_inertia mass="0" radius="0"/>
    <visual>
      <material name="handle_blue"/>
      <origin rpy="1.570796327 0 3.14159265359" xyz="0 0 0"/>
      <geometry>
        <box size="0.15 0.025 0.015"/>
      </geometry>
    </visual>
    <collision>
      <origin rpy="1.570796327 0 3.14159265359" xyz="0 0 0"/>
      <geometry>
        <box size="0.15 0.025 0.015"/>
      </geometry>
    </collision>
  </link>
  <!-- JOINTS -->
  <joint name="door_living-room_sleeping-room_1_door_origin_revolute_joint" type="revolute">
    <axis xyz="0 0 1"/>
    <limit effort="100" lower="0" upper="1.5708" velocity="10"/>
    <origin rpy="0 0 0" xyz="0 0 0"/>
    <parent link="door_living-room_sleeping-room_1_door_hinge"/>
    <child link="door_living-room_sleeping-room_1_door_center"/>
  </joint>
  <joint name="door_living-room_sleeping-room_1_door_hinge_joint" type="fixed">
    <axis xyz="0 0 0"/>
    <limit effort="1" lower="0" upper="1.5708" velocity="1"/>
    <origin rpy="0 0 0" xyz="-1.5 3 1.045"/>
    <parent link="urdf_offset"/>
    <child link="door_living-room_sleeping-room_1_door_hinge"/>
  </joint>
  <joint name="door_living-room_sleeping-room_1_door_handle_inside_joint" type="fixed">
    <axis xyz="0 0 0"/>
    <limit effort="1" lower="0" upper="1.5708" velocity="1"/>
    <origin rpy="0 0 0" xyz="0.9 -0.06875 -0.13"/>
    <parent link="door_living-room_sleeping-room_1_door_center"/>
    <child link="door_living-room_sleeping-room_1_door_handle_inside"/>
  </joint>
  <joint name="door_living-room_sleeping-room_1_door_handle_outside_joint" type="fixed">
    <axis xyz="0 0 0"/>
    <limit effort="1" lower="0" upper="1.5708" velocity="1"/>
    <origin rpy="0 0 0" xyz="0.9 0.055 -0.13"/>
    <parent link="door_living-room_sleeping-room_1_door_center"/>
    <child link="door_living-room_sleeping-room_1_door_handle_outside"/>
  </joint>
  <link name="urdf_main"/>
  <joint name="map_urdf_joint" type="fixed">
    <origin rpy="0 0 0" xyz="0.0 0.0 0 "/>
    <parent link="urdf_main"/>
    <child link="urdf_offset"/>
  </joint>
  <link name="urdf_offset"/>
  <!--ROBOT LINK ONLY FOR TESTING-->
  <link name="base_footprint"/>
  <joint name="base_footprint_joint" type="fixed">
    <origin rpy="0 0 0" xyz="-4.0 -3.0 0.0"/>
    <parent link="urdf_main"/>
    <child link="base_footprint"/>
  </joint>
</robot>
